Dataset nÂº  89
Shape: (1794, 9)(examples, features)
Traceback (most recent call last):
  File "/home/core/anaconda3/envs/PedroAlves/lib/python3.8/site-packages/pandas/core/indexes/base.py", line 2897, in get_loc
    return self._engine.get_loc(key)
  File "pandas/_libs/index.pyx", line 107, in pandas._libs.index.IndexEngine.get_loc
  File "pandas/_libs/index.pyx", line 131, in pandas._libs.index.IndexEngine.get_loc
  File "pandas/_libs/hashtable_class_helper.pxi", line 1607, in pandas._libs.hashtable.PyObjectHashTable.get_item
  File "pandas/_libs/hashtable_class_helper.pxi", line 1614, in pandas._libs.hashtable.PyObjectHashTable.get_item
KeyError: 'bean_type'

During handling of the above exception, another exception occurred:

Traceback (most recent call last):
  File "runClassifier.py", line 118, in <module>
    model = model.fit(Datasets, TargetNames)
  File "/home/core/Documents/PedroAlves/autoBagging/autoBaggingClassifier.py", line 84, in fit
    # MetaFeatures
  File "/home/core/Documents/PedroAlves/autoBagging/autoBaggingClassifier.py", line 384, in _metafeatures
    meta_features['Number of Classes'] = dataset[target].unique().shape[0]
  File "/home/core/anaconda3/envs/PedroAlves/lib/python3.8/site-packages/pandas/core/frame.py", line 2995, in __getitem__
    indexer = self.columns.get_loc(key)
  File "/home/core/anaconda3/envs/PedroAlves/lib/python3.8/site-packages/pandas/core/indexes/base.py", line 2899, in get_loc
    return self._engine.get_loc(self._maybe_cast_indexer(key))
  File "pandas/_libs/index.pyx", line 107, in pandas._libs.index.IndexEngine.get_loc
  File "pandas/_libs/index.pyx", line 131, in pandas._libs.index.IndexEngine.get_loc
  File "pandas/_libs/hashtable_class_helper.pxi", line 1607, in pandas._libs.hashtable.PyObjectHashTable.get_item
  File "pandas/_libs/hashtable_class_helper.pxi", line 1614, in pandas._libs.hashtable.PyObjectHashTable.get_item
KeyError: 'bean_type'
(PedroAlves) core@MTS-WKS-27YG1:~/Documents/PedroAlves/autoBagging$ 

